Workbook

Sheet Key
A1: Haisley · competition options, November 2026 to December 2027
A2: Built 20 October 2026 from the Volleyball Life crawl and CBVA’s tournament database.
A4: Her TruVolley | B4: 9.678 | C4: Her own current rating.
A5: Her pair rating | B5: 9.5 | C5: What a team of hers rates: she enters with partners rated 9.1-9.5, so the teams that outrank her team are the ones averaging above this. Edit this cell and the match-odds column on Beach Pro Tour moves with it.
A6: Peer band | B6: 9.20–10.10 | C6: The rating range counted as “a pair rated like hers” when measuring how many sets a draw actually gives.
A7: Contested | B7: within 0.75 | C7: A set is contested when the opposing pair rates within this of her own. Everything else is a formality.
A8: Calendar entries | B8: 78 | C8: Rows on the Calendar sheet.
A9: Weekend pairs | B9: 7 | C9: Weekends holding two one-day draws within reach of one hotel.
A10: Pro-am draws listed | B10: 18 | C10: Highline and AVP Next women's opens in California since 2025.
A11: Players rated | B11: 2819 | C11: TruVolley ratings held for the entrants behind every field number in the book.
A13: What each kind of date is
A14: Selection | C14: A national-team or ISF trial. The only rows that can put her on a team.
A15: National junior | C15: A national junior championship: the deepest fields she is age-eligible for, and the longest days.
A16: Junior circuit | C16: The p1440 / IBVL / BVNE junior circuit. Regular, shallower, useful for reps and ranking points.
A17: Women's open | C17: An adult draw. Harder opponents than most junior dates, but four sets rather than twenty.
A18: Pro-am open | C18: A promoter's adult open with a purse -- Highline or AVP Next. Harder than CBVA and three times the sets.
A19: Out of reach | C19: Professional or qualification-only. A median above 10.3 and two or three sets before the exit.
A20: Grass | C20: Played on grass, which carries its own TruVolley. Nothing that happens there can move her sand rating.
A22: Two age charts, one year apart
A23: USA Volleyball | C23: NTDP rosters and national-team trials. She is U18 in 2027.
A24: AVP Juniors, AAU, BVCA | C24: The junior championships, labelled a year younger. She is 17U in 2027, and the 18U draws are playing up.
A25: p1440 Futures Tour | C25: Runs 16U and 18U only. She ages out of 16U, so 18U is the only option.
A27: The page this book was built from: https://cormacflanagan.github.io/VB/docs/plan-2027.html

Sheet Calendar
A1: Date | B1: Date is | C1: Days | D1: Event | E1: Venue | F1: State | G1: Draw | H1: Kind | I1: Her band | J1: Field median | K1: Above her | L1: Sets | M1: Contested | N1: Contested share | O1: Weekend pair | P1: Link
A2: 46327 | B2: posted | C2: 1 | D2: America’s Challenge (p1440) | E2: Hermosa Beach Pier | F2: CA | G2: 18U | H2: Junior circuit | N2: =IFERROR(M2/L2,"") | P2: https://volleyballlife.com/tournament/35287
A3: 46333 | B3: posted | C3: 2 | D3: AVP Juniors West Coast Championships | E3: Manhattan Beach | F3: CA | G3: 18U | H3: National junior | J3: 9.5015 | K3: 17 | L3: 14.666667 | M3: 7 | N3: =IFERROR(M3/L3,"") | P3: https://volleyballlife.com/tournament/34245
A4: 46333 | B4: posted | C4: 2 | D4: AVP Juniors West Coast Championships | E4: Manhattan Beach | F4: CA | G4: 17U | H4: National junior | I4: yes | J4: 7.714 | K4: 0 | L4: 15 | M4: 5 | N4: =IFERROR(M4/L4,"") | P4: https://volleyballlife.com/tournament/34245
A5: 46333 | B5: posted | C5: 1 | D5: CBVA women’s open | E5: Belmont Shore, Long Beach | F5: CA | G5: Open | H5: Women's open | J5: 8.711 | K5: 5 | L5: 4 | M5: 1.6666667 | N5: =IFERROR(M5/L5,"") | P5: https://cbva.com/venues/3
A6: 46340 | B6: posted | C6: 1 | D6: p1440 1X Ranking Event | E6: Arizona Athletic Grounds, Mesa | F6: AZ | G6: 18U | H6: Junior circuit | N6: =IFERROR(M6/L6,"") | P6: https://volleyballlife.com/tournament/41163
A7: 46340 | B7: posted | C7: 1 | D7: The National Classic (p1440) | E7: Hermosa Beach Pier | F7: CA | G7: 18U | H7: Junior circuit | J7: 8.597 | K7: 1 | L7: 1 | M7: 0 | N7: =IFERROR(M7/L7,"") | P7: https://volleyballlife.com/tournament/35286
A8: 46340 | B8: posted | C8: 1 | D8: CBVA women’s open | E8: Newland, Huntington Beach | F8: CA | G8: Open | H8: Women's open | J8: 8.769 | K8: 6 | L8: 4.0625 | M8: 1.8125 | N8: =IFERROR(M8/L8,"") | P8: https://cbva.com/venues/4
A9: 46347 | B9: posted | C9: 2 | D9: Futures Tour 3X: Fall Championships | E9: Manhattan Beach | F9: CA | G9: 18U | H9: National junior | I9: yes | N9: =IFERROR(M9/L9,"") | P9: https://volleyballlife.com/tournament/41692
A10: 46347 | B10: posted | C10: 1 | D10: MAVERICKS AVP Qualifier | E10: Main Beach, Santa Cruz | F10: CA | G10: 18U | H10: Junior circuit | J10: 6.429 | K10: 0 | N10: =IFERROR(M10/L10,"") | P10: https://volleyballlife.com/tournament/35628
A11: 46347 | B11: posted | C11: 1 | D11: CBVA women’s open | E11: North Beach, Santa Monica | F11: CA | G11: Open | H11: Women's open | K11: 0 | N11: =IFERROR(M11/L11,"") | O11: 21 Nov + 22 Nov | P11: https://cbva.com/venues/16
A12: 46348 | B12: posted | C12: 1 | D12: CBVA women’s open | E12: Main Beach, Laguna Beach | F12: CA | G12: Open | H12: Women's open | J12: 8.929 | K12: 4 | L12: 6.5 | M12: 5.5 | N12: =IFERROR(M12/L12,"") | O12: 21 Nov + 22 Nov | P12: https://cbva.com/venues/5
A13: 46368 | B13: posted | C13: 1 | D13: AVP Winter Las Vegas | E13: Sunset Park, Las Vegas | F13: NV | G13: 18U | H13: Junior circuit | J13: 6.2515 | K13: 0 | N13: =IFERROR(M13/L13,"") | P13: https://volleyballlife.com/tournament/41138
A14: 46368 | B14: posted | C14: 1 | D14: p1440 1X Ranking Event | E14: Arizona Athletic Grounds, Mesa | F14: AZ | G14: 18U | H14: Junior circuit | N14: =IFERROR(M14/L14,"") | P14: https://volleyballlife.com/tournament/41164
A15: 46369 | B15: posted | C15: 1 | D15: Los Angeles Grand Prix (p1440) | E15: Hermosa Beach Pier | F15: CA | G15: 18U | H15: Junior circuit | J15: 9.1305 | K15: 6 | L15: 2.5 | M15: 1 | N15: =IFERROR(M15/L15,"") | P15: https://volleyballlife.com/tournament/32937
A16: 46369 | B16: posted | C16: 1 | D16: Pan Pacific Championships (p1440) | E16: Hermosa Beach Pier | F16: CA | G16: 18U | H16: Junior circuit | J16: 8.743 | K16: 0 | L16: 2 | M16: 1 | N16: =IFERROR(M16/L16,"") | P16: https://volleyballlife.com/tournament/35288
A17: 46386 | B17: posted | C17: 1 | D17: IBVL Winter Series #1 (Girls) | E17: Hermosa Beach Pier | F17: CA | G17: 18U | H17: Junior circuit | J17: 9.0765 | K17: 8 | L17: 7.75 | M17: 4 | N17: =IFERROR(M17/L17,"") | P17: https://volleyballlife.com/tournament/41068
A18: 46396 | B18: posted | C18: 1 | D18: p1440 1X Ranking Event | E18: Arizona Athletic Grounds, Mesa | F18: AZ | G18: 18U | H18: Junior circuit | N18: =IFERROR(M18/L18,"") | P18: https://volleyballlife.com/tournament/41165
A19: 46397 | B19: posted | C19: 1 | D19: IBVL Winter Classic (Girls p1440) | E19: Hermosa Beach Pier | F19: CA | G19: 18U | H19: Junior circuit | J19: 9.0765 | K19: 8 | L19: 7.75 | M19: 4 | N19: =IFERROR(M19/L19,"") | P19: https://volleyballlife.com/tournament/41069
A20: 46403 | B20: posted | C20: 2 | D20: Futures Tour 2X: Arizona | E20: Arizona Athletic Grounds, Mesa | F20: AZ | G20: 18U | H20: Junior circuit | I20: yes | J20: 8.286 | K20: 9 | L20: 21 | M20: 8.25 | N20: =IFERROR(M20/L20,"") | P20: https://volleyballlife.com/tournament/41707
A21: 46410 | B21: posted | C21: 2 | D21: IBVL Winter Nationals (Girls) | E21: Hermosa Beach Pier | F21: CA | G21: 18U | H21: Junior circuit | J21: 9.485 | K21: 4 | L21: 16 | M21: 11 | N21: =IFERROR(M21/L21,"") | P21: https://volleyballlife.com/tournament/41070
A22: 46416 | B22: estimated | C22: 2 | D22: USAV U18 Beach National Team Trials | E22: Manhattan Beach Pier | F22: CA | G22: 18U | H22: Selection | I22: yes | J22: 9.4015 | K22: 4 | L22: 12.5 | M22: 9.5 | N22: =IFERROR(M22/L22,"") | P22: https://volleyballlife.com/tournament/34180
A23: 46424 | B23: posted | C23: 1 | D23: Kauai Bikini Open | E23: North Beach, Santa Monica | F23: CA | G23: 18U | H23: Junior circuit | J23: 7.224 | K23: 0 | N23: =IFERROR(M23/L23,"") | O23: 6 Feb + 7 Feb | P23: https://volleyballlife.com/tournament/41121
A24: 46425 | B24: posted | C24: 1 | D24: IBVL Winter Nationals (School Event) — ISF trial | E24: Hermosa Beach Pier | F24: CA | G24: 18U | H24: Selection | I24: yes | J24: 9.485 | K24: 4 | L24: 16 | M24: 11 | N24: =IFERROR(M24/L24,"") | O24: 6 Feb + 7 Feb | P24: https://volleyballlife.com/tournament/41071
A25: 46431 | B25: posted | C25: 1 | D25: p1440 1X Ranking Event | E25: Arizona Athletic Grounds, Mesa | F25: AZ | G25: 18U | H25: Junior circuit | N25: =IFERROR(M25/L25,"") | P25: https://volleyballlife.com/tournament/41166
A26: 46445 | B26: estimated | C26: 1 | D26: Highline Sponsorship Open ($5K) | E26: Ocean Park North, Santa Monica | F26: CA | G26: Open | H26: Out of reach | J26: 10.0125 | K26: 17 | L26: 5.5 | M26: 3.25 | N26: =IFERROR(M26/L26,"") | P26: https://volleyballlife.com/tournament/36177
A27: 46453 | B27: posted | C27: 1 | D27: California IBVL Winter Series Championships (p1440) | E27: Hermosa Beach Pier | F27: CA | G27: 18U | H27: Junior circuit | J27: 8.922 | K27: 1 | L27: 8.3333333 | M27: 8 | N27: =IFERROR(M27/L27,"") | O27: 6 Mar + 7 Mar | P27: https://volleyballlife.com/tournament/41072
A28: 46467 | B28: posted | C28: 1 | D28: Marine Open (Girls p1440) | E28: Manhattan Beach Lifeguard HQ | F28: CA | G28: 18U | H28: Junior circuit | K28: 0 | N28: =IFERROR(M28/L28,"") | O28: 20 Mar + 21 Mar | P28: https://volleyballlife.com/tournament/41074
A29: 46452 | B29: projected | C29: 1 | D29: CBVA women’s open | E29: Manhattan Pier, Manhattan Beach | F29: CA | G29: Open | H29: Women's open | J29: 9.1665 | K29: 6 | L29: 9.2666667 | M29: 5.9333333 | N29: =IFERROR(M29/L29,"") | O29: 6 Mar + 7 Mar | P29: https://cbva.com/venues/2
A30: 46466 | B30: projected | C30: 1 | D30: CBVA women’s open | E30: Newland, Huntington Beach | F30: CA | G30: Open | H30: Women's open | J30: 9.088 | K30: 8 | L30: 4.5238095 | M30: 3.047619 | N30: =IFERROR(M30/L30,"") | O30: 20 Mar + 21 Mar | P30: https://cbva.com/venues/4
A31: 46474 | B31: projected | C31: 1 | D31: CBVA women’s open | E31: Dockweiler, Los Angeles | F31: CA | G31: Open | H31: Women's open | J31: 8.755 | K31: 2 | L31: 5.25 | M31: 0.75 | N31: =IFERROR(M31/L31,"") | P31: https://cbva.com/venues/1
A32: 46480 | B32: posted | C32: 2 | D32: Futures Tour 2X: California | E32: North Beach, Santa Monica | F32: CA | G32: 18U | H32: Junior circuit | I32: yes | N32: =IFERROR(M32/L32,"") | P32: https://volleyballlife.com/tournament/41882
A33: 46495 | B33: posted | C33: 1 | D33: p1440 Hermosa Beach Circuit Championships (2X) | E33: Hermosa Beach Pier | F33: CA | G33: 18U | H33: Junior circuit | J33: 9.414 | K33: 7 | L33: 5.25 | M33: 3.25 | N33: =IFERROR(M33/L33,"") | P33: https://volleyballlife.com/tournament/41075
A34: 46488 | B34: projected | C34: 1 | D34: CBVA women’s open | E34: Ocean Park, Santa Monica | F34: CA | G34: Open | H34: Women's open | J34: 9.015 | K34: 6 | L34: 4.2666667 | M34: 2.8666667 | N34: =IFERROR(M34/L34,"") | P34: https://cbva.com/venues/7
A35: 46501 | B35: projected | C35: 1 | D35: CBVA women’s open | E35: Manhattan Pier, Manhattan Beach | F35: CA | G35: Open | H35: Women's open | J35: 8.885 | K35: 7 | L35: 3.5333333 | M35: 1.3333333 | N35: =IFERROR(M35/L35,"") | P35: https://cbva.com/venues/2
A36: 46501 | B36: projected | C36: 1 | D36: CBVA women’s open | E36: Main Beach, Santa Cruz | F36: CA | G36: Open | H36: Women's open | J36: 7.68 | K36: 1 | L36: 3.6666667 | M36: 0.66666667 | N36: =IFERROR(M36/L36,"") | P36: https://cbva.com/venues/8
A37: 46522 | B37: projected | C37: 1 | D37: CBVA women’s open | E37: Ocean Park, Santa Monica | F37: CA | G37: Open | H37: Women's open | J37: 8.757 | K37: 3 | L37: 3.7777778 | M37: 2 | N37: =IFERROR(M37/L37,"") | O37: 15 May + 16 May | P37: https://cbva.com/venues/7
A38: 46523 | B38: projected | C38: 1 | D38: CBVA women’s open | E38: Belmont Shore, Long Beach | F38: CA | G38: Open | H38: Women's open | J38: 8.757 | K38: 4 | L38: 4.25 | M38: 1.75 | N38: =IFERROR(M38/L38,"") | O38: 15 May + 16 May | P38: https://cbva.com/venues/3
A39: 46508 | B39: projected | C39: 1 | D39: CBVA women’s open | E39: Manhattan Pier, Manhattan Beach | F39: CA | G39: Open | H39: Women's open | J39: 8.826 | K39: 4 | L39: 3.75 | M39: 1.25 | N39: =IFERROR(M39/L39,"") | P39: https://cbva.com/venues/2
A40: 46536 | B40: projected | C40: 1 | D40: CBVA women’s open | E40: Ocean Beach, San Diego | F40: CA | G40: Open | H40: Women's open | J40: 7.783 | K40: 3 | L40: 3 | M40: 1 | N40: =IFERROR(M40/L40,"") | P40: https://cbva.com/venues/13
...

Sheet Weekend pairs
A1: Saturday | B1: Saturday event | C1: Saturday venue | D1: Sunday | E1: Sunday event | F1: Sunday venue | G1: Miles | H1: Minutes | I1: Sat contested | J1: Sun contested | K1: Weekend total | L1: Dates
A2: 46347 | B2: CBVA women’s open | C2: North Beach, Santa Monica | D2: 46348 | E2: CBVA women’s open | F2: Main Beach, Laguna Beach | G2: 52 | H2: 70 | J2: 5.5 | K2: =SUM(I2:J2) | L2: Both posted
A3: 46424 | B3: Kauai Bikini Open | C3: North Beach, Santa Monica | D3: 46425 | E3: IBVL Winter Nationals (School Event) — ISF trial | F3: Hermosa Beach Pier | G3: 13 | H3: 30 | J3: 11 | K3: =SUM(I3:J3) | L3: Both posted
A4: 46452 | B4: CBVA women’s open | C4: Manhattan Pier, Manhattan Beach | D4: 46453 | E4: California IBVL Winter Series Championships (p1440) | F4: Hermosa Beach Pier | G4: 3 | H4: 10 | I4: 5.9333333 | J4: 8 | K4: =SUM(I4:J4) | L4: One posted, one projected
A5: 46466 | B5: CBVA women’s open | C5: Newland, Huntington Beach | D5: 46467 | E5: Marine Open (Girls p1440) | F5: Manhattan Beach Lifeguard HQ | G5: 33 | H5: 45 | I5: 3.047619 | K5: =SUM(I5:J5) | L5: One posted, one projected
A6: 46522 | B6: CBVA women’s open | C6: Ocean Park, Santa Monica | D6: 46523 | E6: CBVA women’s open | F6: Belmont Shore, Long Beach | G6: 30 | H6: 45 | I6: 2 | J6: 1.75 | K6: =SUM(I6:J6) | L6: Both projected
A7: 46543 | B7: Kauai Bikini Open | C7: North Beach, Santa Monica | D7: 46544 | E7: CBVA women’s open | F7: Dockweiler, Los Angeles | G7: 8 | H7: 20 | J7: 2.7142857 | K7: =SUM(I7:J7) | L7: One posted, one projected
A8: 46543 | B8: Kauai Bikini Open | C8: North Beach, Santa Monica | D8: 46544 | E8: CBVA women’s open | F8: Ocean Park, Santa Monica | G8: 1 | H8: 5 | J8: 1.75 | K8: =SUM(I8:J8) | L8: One posted, one projected
A10: Two one-day draws on the two days of one weekend, within reach of one hotel. A weekend total with a blank beside it is a floor: the corpus carries no bracket for the Kauai Bikini Open or the Marine Open, so their sets are unknown rather than zero. Miles and minutes are approximate road distances read off the map.

Sheet Pro-am circuit
A1: Date | B1: Series | C1: Event | D1: Venue | E1: Days | F1: Teams | G1: Field median | H1: Above her | I1: Sets | J1: Contested | K1: Contested share | L1: Rated pairs | M1: Link
A2: 45816 | B2: Highline | C2: Soli / Highline - Open Tournament | D2: Ocean Park North Volleyball Courts | E2: 1 | F2: 20 | G2: 9.62 | H2: 17 | I2: 6.1666667 | J2: 3.3333333 | K2: =IFERROR(J2/I2,"") | L2: 6 | M2: https://volleyballlife.com/tournament/28813
A3: 45857 | B3: Highline | C3: Highline Women's Open | D3: Dockweiler State Beach | E3: 1 | F3: 18 | G3: 9.9715 | H3: 18 | I3: 10 | J3: 3.75 | K3: =IFERROR(J3/I3,"") | L3: 4 | M3: https://volleyballlife.com/tournament/30939
A4: 45892 | B4: Highline | C4: Highline x WITH - The Santa Monica Open $10K | D4: Ocean Park North Volleyball Courts | E4: 2 | F4: 20 | G4: 9.777 | H4: 16 | I4: 9.8571429 | J4: 4.2857143 | K4: =IFERROR(J4/I4,"") | L4: 7 | M4: https://volleyballlife.com/tournament/30355
A5: 45933 | B5: AVP Next | C5: The Santa Barbara Open- AVP Next | D5: Santa Barbara | E5: 3 | F5: 32 | G5: 9.6455 | H5: 27 | I5: 11.333333 | J5: 5 | K5: =IFERROR(J5/I5,"") | L5: 9 | M5: https://volleyballlife.com/tournament/28899
A6: 45977 | B6: Highline | C6: Mad Hippie Highline Open | D6: Manhattan Beach Pier | E6: 1 | F6: 16 | G6: 10.002 | H6: 18 | I6: 7.1666667 | J6: 3.8333333 | K6: =IFERROR(J6/I6,"") | L6: 6 | M6: https://volleyballlife.com/tournament/33832
A7: 46074 | B7: Highline | C7: Men's/Women's Open - AVP League Format | D7: 2400 Ocean Front Walk | E7: 1 | F7: 12 | G7: 9.9845 | H7: 13 | I7: 12 | J7: 6.6 | K7: =IFERROR(J7/I7,"") | L7: 5 | M7: https://volleyballlife.com/tournament/35531
A8: 46081 | B8: Highline | C8: Highline Sponsorship Open ($5K) | D8: Ocean Park North | E8: 1 | F8: 17 | G8: 10.0125 | H8: 17 | I8: 5.5 | J8: 3.25 | K8: =IFERROR(J8/I8,"") | L8: 4 | M8: https://volleyballlife.com/tournament/36177
A9: 46089 | B9: Highline | C9: Men's/Women's Open - “League” Format | D9: Manhattan Beach Pier South | E9: 1 | F9: 11 | G9: 9.431 | H9: 10 | I9: 11.4 | J9: 6 | K9: =IFERROR(J9/I9,"") | L9: 5 | M9: https://volleyballlife.com/tournament/36426
A10: 46116 | B10: Highline | C10: Highline x HOBVF x Beach United - Men's/Women's Open | D10: The Huntington Beach Courts | E10: 1 | F10: 13 | G10: 9.398 | H10: 7 | I10: 10.333333 | J10: 5 | K10: =IFERROR(J10/I10,"") | L10: 3 | M10: https://volleyballlife.com/tournament/37280
A11: 46122 | B11: AVP Next | C11: AVP NEXT Huntington Beach Series - $8,000 Purse | D11: Beach Elite Volleyball Courts @ Brookhurst Street | E11: 2 | F11: 14 | G11: 9.904 | H11: 16 | K11: =IFERROR(J11/I11,"") | L11: 0 | M11: https://volleyballlife.com/tournament/36208
A12: 46173 | B12: Highline | C12: Highline - Men's/Women's Open $3K | D12: East Beach, Santa Barbara | E12: 1 | F12: 13 | G12: 8.574 | H12: 2 | I12: 12 | J12: 9 | K12: =IFERROR(J12/I12,"") | L12: 1 | M12: https://volleyballlife.com/tournament/37912
A13: 46186 | B13: Highline | C13: Highline - Men's/Women's Open | D13: Ocean Park North | E13: 1 | F13: 17 | G13: 10.09 | H13: 14 | I13: 5.5 | J13: 2.25 | K13: =IFERROR(J13/I13,"") | L13: 4 | M13: https://volleyballlife.com/tournament/38944
A14: 46222 | B14: Highline | C14: Highline - Men's/Women's Open $2.5K | D14: East Beach, Santa Barbara | E14: 1 | F14: 15 | G14: 8.258 | H14: 5 | I14: 12 | J14: 5 | K14: =IFERROR(J14/I14,"") | L14: 2 | M14: https://volleyballlife.com/tournament/39873
A15: 46228 | B15: Highline | C15: Highline - Men's/Women's $2.5K | D15: Coronado Beach | E15: 1 | F15: 9 | G15: 7.365 | H15: 0 | I15: 9 | J15: 0 | K15: =IFERROR(J15/I15,"") | L15: 1 | M15: https://volleyballlife.com/tournament/39874
A16: 46256 | B16: AVP Next | C16: Highline - Santa Monica AVP NEXT | D16: Santa Monica Pier | E16: 2 | F16: 17 | G16: 9.9345 | H16: 16 | I16: 8.8 | J16: 6 | K16: =IFERROR(J16/I16,"") | L16: 5 | M16: https://volleyballlife.com/tournament/34776
A17: 46285 | B17: Highline | C17: Highline - Men's/Women's $2.5K | D17: Coronado Beach | E17: 1 | F17: 10 | G17: 7.8395 | H17: 0 | K17: =IFERROR(J17/I17,"") | L17: 0 | M17: https://volleyballlife.com/tournament/41301
A18: 46313 | B18: Highline | C18: Highline - Men's A / Women's A / Women's Open | D18: Coronado Beach | E18: 1 | F18: 12 | G18: 7.652 | H18: 0 | K18: =IFERROR(J18/I18,"") | L18: 0 | M18: https://volleyballlife.com/tournament/41947
A19: 46313 | B19: Highline | C19: Highline - Men's A / Women's A / Women's Open | D19: Coronado Beach | E19: 1 | F19: 19 | G19: 6.292 | H19: 0 | K19: =IFERROR(J19/I19,"") | L19: 0 | M19: https://volleyballlife.com/tournament/41947
A21: Every Highline or AVP Next women's open draw in California since 2025. Rated pairs is how many pairs rated within her own band were in that draw, and it is the sample the sets and contested columns rest on: a figure resting on one or two pairs is one or two teams' afternoon, not a property of the event. The medians and the count above her rest on the whole entry list.

Sheet Beach Pro Tour
A1: Tier | B1: Where | C1: US entrants rated | D1: Field median | E1: Weakest | F1: Below her | G1: Her match odds
A2: Mexico Elite16 | B2: Tepic, Quintana Roo | C2: 22 | D2: 12.6125 | E2: 10.727 | F2: 0 | G2: =1/(1+EXP(D2-Key!$B$5))
A3: Mexico Challenge | B3: Tlaxcala, Nayarit, Yucatan, Veracruz, Guadalajara, La Paz | C3: 138 | D3: 11.609 | E3: 9.198 | F3: 0.086956522 | G3: =1/(1+EXP(D3-Key!$B$5))
A4: Elite16, worldwide | B4: the sixteen-team top tier | C4: 712 | D4: 12.352 | E4: 9.081 | F4: 0.0028089888 | G4: =1/(1+EXP(D4-Key!$B$5))
A5: Challenge, worldwide | B5: the tier below it | C5: 322 | D5: 11.58 | E5: 8.367 | F5: 0.031055901 | G5: =1/(1+EXP(D5-Key!$B$5))
A6: Futures, the Americas | B6: Pompano Beach FL, Halifax CAN - never Mexico | C6: 49 | D6: 10.666 | E6: 7.701 | F6: 0.24489796 | G6: =1/(1+EXP(D6-Key!$B$5))
A7: Futures, worldwide | B7: mostly Europe and China | C7: 491 | D7: 9.971 | E7: 4.776 | F7: 0.38289206 | G7: =1/(1+EXP(D7-Key!$B$5))
A9: The star ratings belonged to the FIVB World Tour, whose last season was 2021; the Beach Pro Tour replaced it in 2022 with Futures, Challenge and Elite16, of which Futures is roughly where the old one-star sat. There has never been a Futures in Mexico. Ratings are the American entrants in each draw, because the US entry list is the one she would have to be on. Match odds are the logistic fitted to 7,000 rated CBVA women's matches, applied to her pair rating on Key.
